Workbook

Sheet Cover
A1: APEX INDUSTRIAL TECHNOLOGIES LTD.
A3: Financial Analysis, Forecasting & Valuation
A5: Portfolio project | Historical FY2021–FY2026 | Forecast FY2027–FY2029
A7: Purpose
A8: Build an analyst-grade model covering financial statements, ratios, working capital, forecasting, Bull/Base/Bear scenarios, DCF valuation with a CAPM-based WACC build and sensitivity analysis.
A10: Workbook guide
A12: Executive Summary | B12: Investment thesis, KPI snapshot and DCF-based valuation rating
A13: Raw Data | B13: Historical operating, segment, geography and cash-flow inputs
A14: Income Statement | B14: Historical P&L with calculated profitability
A15: Balance Sheet | B15: Historical balance sheet with assets, liabilities and equity
A16: Cash Flow | B16: FCF bridge and cash-flow analysis
A17: Ratios | B17: Growth, margins, liquidity, leverage and returns
A18: Revenue Analysis | B18: Segment and geographic revenue mix
A19: Working Capital | B19: DSO, DIO, DPO and cash conversion cycle
A20: Forecast | B20: FY2027–FY2029 base-case forecast
A21: Scenario Analysis | B21: Bull / Base / Bear case comparison with scenario-level DCF valuation
A22: DCF | B22: Free cash flow valuation, CAPM WACC build-up and sensitivity grid
A23: Dashboard | B23: Management-style KPI dashboard

Sheet Executive Summary
A1: Executive Summary
A3: Apex Industrial Technologies Ltd. — Illustrative Portfolio Model (Fictional Company)
A5: Investment Snapshot — FY2026 Actual vs. FY2029E (Base Case)
A6: Metric | B6: FY2026 (Actual) | C6: FY2029E (Base) | D6: CAGR / Δ (pts)
A7: Revenue (₹ crore) | B7: ='Income Statement'!G4 -> 780 | C7: =Forecast!J4 -> 1010.0376 | D7: =(C7/B7)^(1/3)-1 -> 0.089969418
A8: EBITDA (₹ crore) | B8: ='Income Statement'!G8 -> 150 | C8: =Forecast!J9 -> 211.09786 | D8: =(C8/B8)^(1/3)-1 -> 0.12063502
A9: EBITDA Margin | B9: ='Income Statement'!G16 -> 0.19230769 | C9: =C8/C7 -> 0.209 | D9: =C9-B9 -> 0.016692308
A10: Net Profit (₹ crore) | B10: ='Income Statement'!G14 -> 85 | C10: =Forecast!J14 -> 122.1126 | D10: =(C10/B10)^(1/3)-1 -> 0.12835872
A11: Net Profit Margin | B11: ='Income Statement'!G18 -> 0.10897436 | C11: =C10/C7 -> 0.12089907 | D11: =C11-B11 -> 0.011924709
A12: Free Cash Flow (₹ crore) | B12: ='Cash Flow'!G10 -> 89 | C12: =Forecast!J17 -> 81.7111 | D12: =(C12/B12)^(1/3)-1 -> -0.028080377
A13: Return on Equity (ROE) | B13: =Ratios!G14 -> 0.26479751
A14: Debt / EBITDA | B14: =Ratios!G11 -> 1.3133333
A15: Cash Conversion Cycle (days) | B15: ='Working Capital'!G7 -> 84.579813
A17: Investment Thesis
A18: • Consistent double-digit growth: revenue compounded at a 13.2% CAGR from ₹420 cr (FY21) to ₹780 cr (FY26), led by the Industrial Automation and Motion Control segments.
A19: • Margin expansion: EBITDA margin improved from 15.5% (FY21) to 19.2% (FY26) as operating leverage built through the revenue base.
A20: • Deleveraging balance sheet: Debt/EBITDA fell from 2.08x to 1.31x and Debt/Equity from 0.87x to 0.61x over FY21–FY26, widening headroom for growth capex.
A21: • Strong cash conversion: Free Cash Flow grew from ₹37 cr to ₹89 cr (FY21–FY26), funding capex and debt paydown without external financing.
A22: • Diversified base: revenue is split across 3 product segments and 4 geographies, with India as the core market (~72% of FY26 revenue) and export markets providing incremental growth optionality.
A24: Key Risks & Watch Items
A25: • Working capital intensity: Cash Conversion Cycle of ~85 days (FY26) ties up cash as the business scales — DIO in particular has drifted up ~5 days since FY21.
A26: • Customer/capex cyclicality: revenue is tied to industrial capex cycles; a slowdown in manufacturing investment could compress order intake and growth.
A27: • Margin assumptions in the forecast (COGS ~62–63% of revenue) assume continued procurement efficiency; input-cost inflation is a downside risk.
A28: • Valuation is sensitive to WACC and terminal growth — see the DCF sensitivity grid for a ±1pt range on both.
A30: Valuation Summary & Illustrative Rating
A31: DCF Implied Value / Share — Base Case (₹) | B31: =DCF!B21 -> 79.786122
A32: DCF Implied Value / Share — Bear Case (₹) | B32: ='Scenario Analysis'!G42 -> 65.29646
A33: DCF Implied Value / Share — Bull Case (₹) | B33: ='Scenario Analysis'!G44 -> 95.425005
A34: Illustrative Current Market Price (₹) | B34: 72
A35: Upside / (Downside) to Base Case | B35: =B31/B34-1 -> 0.10814058
A36: Illustrative Rating | B36: =IF(B35>0.15,"BUY",IF(B35<-0.15,"SELL","HOLD")) -> HOLD
A38: Illustrative only — this is a self-directed portfolio project on a fictional company. The market price and rating are for demonstration and are not investment advice.

Sheet Raw Data
A1: Historical Input Data (₹ crore)
A3: Income Statement Inputs
A4: FY | B4: Revenue | C4: COGS | D4: Operating Expenses | E4: Depreciation | F4: Interest Expense | G4: Tax
A5: 2021 | B5: 420 | C5: 273 | D5: 82 | E5: 12 | F5: 10 | G5: 8
A6: 2022 | B6: 465 | C6: 300 | D6: 91 | E6: 13 | F6: 11 | G6: 10
A7: 2023 | B7: 520 | C7: 333 | D7: 101 | E7: 15 | F7: 12 | G7: 13
A8: 2024 | B8: 590 | C8: 372 | D8: 112 | E8: 17 | F8: 13 | G8: 16
A9: 2025 | B9: 675 | C9: 425 | D9: 125 | E9: 20 | F9: 15 | G9: 21
A10: 2026 | B10: 780 | C10: 488 | D10: 142 | E10: 23 | F10: 17 | G10: 25
A12: Balance Sheet Inputs
A13: FY | B13: Cash & Equivalents | C13: Accounts Receivable | D13: Inventory | E13: Other Current Assets | F13: Net PPE | G13: Other Non-current Assets | H13: Accounts Payable | I13: Other Current Liabilities | J13: Short-term Debt | K13: Long-term Debt | L13: Other Non-current Liabilities
A14: 2021 | B14: 38 | C14: 68 | D14: 72 | E14: 14 | F14: 145 | G14: 38 | H14: 54 | I14: 31 | J14: 24 | K14: 92 | L14: 19
A15: 2022 | B15: 44 | C15: 75 | D15: 79 | E15: 16 | F15: 154 | G15: 41 | H15: 60 | I15: 34 | J15: 26 | K15: 96 | L15: 21
A16: 2023 | B16: 52 | C16: 84 | D16: 88 | E16: 18 | F16: 168 | G16: 45 | H16: 67 | I16: 39 | J16: 29 | K16: 101 | L16: 23
A17: 2024 | B17: 61 | C17: 96 | D17: 101 | E17: 20 | F17: 184 | G17: 49 | H17: 76 | I17: 45 | J17: 32 | K17: 108 | L17: 26
A18: 2025 | B18: 76 | C18: 111 | D18: 118 | E18: 23 | F18: 207 | G18: 55 | H18: 89 | I18: 52 | J18: 36 | K18: 116 | L18: 29
A19: 2026 | B19: 95 | C19: 128 | D19: 136 | E19: 27 | F19: 235 | G19: 61 | H19: 103 | I19: 61 | J19: 40 | K19: 124 | L19: 33
A21: Revenue by Segment
A22: FY | B22: Industrial Automation | C22: Motion Control | D22: Service & Spares
A23: 2021 | B23: 170 | C23: 135 | D23: 115
A24: 2022 | B24: 190 | C24: 149 | D24: 126
A25: 2023 | B25: 214 | C25: 166 | D25: 140
A26: 2024 | B26: 244 | C26: 188 | D26: 158
A27: 2025 | B27: 281 | C27: 215 | D27: 179
A28: 2026 | B28: 327 | C28: 248 | D28: 205
A30: Revenue by Geography
A31: FY | B31: India | C31: Middle East | D31: Southeast Asia | E31: Europe
A32: 2021 | B32: 300 | C32: 55 | D32: 40 | E32: 25
A33: 2022 | B33: 330 | C33: 61 | D33: 44 | E33: 30
A34: 2023 | B34: 370 | C34: 68 | D34: 48 | E34: 34
A35: 2024 | B35: 420 | C35: 76 | D35: 54 | E35: 40
A36: 2025 | B36: 485 | C36: 86 | D36: 61 | E36: 43
A37: 2026 | B37: 560 | C37: 98 | D37: 70 | E37: 52
A39: Cash Flow Inputs
A40: FY | B40: Capex | C40: Change in Working Capital | D40: Other Operating Cash Flow | E40: Debt Repayment
A41: 2021 | B41: 22 | C41: 8 | D41: 4 | E41: 12
A42: 2022 | B42: 25 | C42: 6 | D42: 5 | E42: 10
A43: 2023 | B43: 28 | C43: 9 | D43: 6 | E43: 9
A44: 2024 | B44: 31 | C44: 11 | D44: 7 | E44: 8
A45: 2025 | B45: 38 | C45: 14 | D45: 9 | E45: 7
...

Sheet Income Statement
A1: Income Statement & Profitability
A3: ₹ crore | B3: 2021 | C3: 2022 | D3: 2023 | E3: 2024 | F3: 2025 | G3: 2026
A4: Revenue | B4: ='Raw Data'!B5 -> 420 | C4: ='Raw Data'!B6 -> 465 | D4: ='Raw Data'!B7 -> 520 | E4: ='Raw Data'!B8 -> 590 | F4: ='Raw Data'!B9 -> 675 | G4: ='Raw Data'!B10 -> 780
A5: COGS | B5: ='Raw Data'!C5 -> 273 | C5: ='Raw Data'!C6 -> 300 | D5: ='Raw Data'!C7 -> 333 | E5: ='Raw Data'!C8 -> 372 | F5: ='Raw Data'!C9 -> 425 | G5: ='Raw Data'!C10 -> 488
A6: Gross Profit | B6: =B4-B5 -> 147 | C6: =C4-C5 -> 165 | D6: =D4-D5 -> 187 | E6: =E4-E5 -> 218 | F6: =F4-F5 -> 250 | G6: =G4-G5 -> 292
A7: Operating Expenses | B7: ='Raw Data'!D5 -> 82 | C7: ='Raw Data'!D6 -> 91 | D7: ='Raw Data'!D7 -> 101 | E7: ='Raw Data'!D8 -> 112 | F7: ='Raw Data'!D9 -> 125 | G7: ='Raw Data'!D10 -> 142
A8: EBITDA | B8: =B6-B7 -> 65 | C8: =C6-C7 -> 74 | D8: =D6-D7 -> 86 | E8: =E6-E7 -> 106 | F8: =F6-F7 -> 125 | G8: =G6-G7 -> 150
A9: Depreciation | B9: ='Raw Data'!E5 -> 12 | C9: ='Raw Data'!E6 -> 13 | D9: ='Raw Data'!E7 -> 15 | E9: ='Raw Data'!E8 -> 17 | F9: ='Raw Data'!E9 -> 20 | G9: ='Raw Data'!E10 -> 23
A10: EBIT | B10: =B8-B9 -> 53 | C10: =C8-C9 -> 61 | D10: =D8-D9 -> 71 | E10: =E8-E9 -> 89 | F10: =F8-F9 -> 105 | G10: =G8-G9 -> 127
A11: Interest Expense | B11: ='Raw Data'!F5 -> 10 | C11: ='Raw Data'!F6 -> 11 | D11: ='Raw Data'!F7 -> 12 | E11: ='Raw Data'!F8 -> 13 | F11: ='Raw Data'!F9 -> 15 | G11: ='Raw Data'!F10 -> 17
A12: PBT | B12: =B10-B11 -> 43 | C12: =C10-C11 -> 50 | D12: =D10-D11 -> 59 | E12: =E10-E11 -> 76 | F12: =F10-F11 -> 90 | G12: =G10-G11 -> 110
A13: Tax | B13: ='Raw Data'!G5 -> 8 | C13: ='Raw Data'!G6 -> 10 | D13: ='Raw Data'!G7 -> 13 | E13: ='Raw Data'!G8 -> 16 | F13: ='Raw Data'!G9 -> 21 | G13: ='Raw Data'!G10 -> 25
A14: Net Profit | B14: =B12-B13 -> 35 | C14: =C12-C13 -> 40 | D14: =D12-D13 -> 46 | E14: =E12-E13 -> 60 | F14: =F12-F13 -> 69 | G14: =G12-G13 -> 85
A15: Gross Margin | B15: =B6/B4 -> 0.35 | C15: =C6/C4 -> 0.35483871 | D15: =D6/D4 -> 0.35961538 | E15: =E6/E4 -> 0.36949153 | F15: =F6/F4 -> 0.37037037 | G15: =G6/G4 -> 0.37435897
A16: EBITDA Margin | B16: =B8/B4 -> 0.1547619 | C16: =C8/C4 -> 0.15913978 | D16: =D8/D4 -> 0.16538462 | E16: =E8/E4 -> 0.17966102 | F16: =F8/F4 -> 0.18518519 | G16: =G8/G4 -> 0.19230769
A17: EBIT Margin | B17: =B10/B4 -> 0.12619048 | C17: =C10/C4 -> 0.1311828 | D17: =D10/D4 -> 0.13653846 | E17: =E10/E4 -> 0.15084746 | F17: =F10/F4 -> 0.15555556 | G17: =G10/G4 -> 0.16282051
A18: Net Profit Margin | B18: =B14/B4 -> 0.083333333 | C18: =C14/C4 -> 0.086021505 | D18: =D14/D4 -> 0.088461538 | E18: =E14/E4 -> 0.10169492 | F18: =F14/F4 -> 0.10222222 | G18: =G14/G4 -> 0.10897436

Sheet Balance Sheet
A1: Balance Sheet
A3: ₹ crore | B3: 2021 | C3: 2022 | D3: 2023 | E3: 2024 | F3: 2025 | G3: 2026
A4: Cash & Equivalents | B4: ='Raw Data'!B14 -> 38 | C4: ='Raw Data'!B15 -> 44 | D4: ='Raw Data'!B16 -> 52 | E4: ='Raw Data'!B17 -> 61 | F4: ='Raw Data'!B18 -> 76 | G4: ='Raw Data'!B19 -> 95
A5: Accounts Receivable | B5: ='Raw Data'!C14 -> 68 | C5: ='Raw Data'!C15 -> 75 | D5: ='Raw Data'!C16 -> 84 | E5: ='Raw Data'!C17 -> 96 | F5: ='Raw Data'!C18 -> 111 | G5: ='Raw Data'!C19 -> 128
A6: Inventory | B6: ='Raw Data'!D14 -> 72 | C6: ='Raw Data'!D15 -> 79 | D6: ='Raw Data'!D16 -> 88 | E6: ='Raw Data'!D17 -> 101 | F6: ='Raw Data'!D18 -> 118 | G6: ='Raw Data'!D19 -> 136
A7: Other Current Assets | B7: ='Raw Data'!E14 -> 14 | C7: ='Raw Data'!E15 -> 16 | D7: ='Raw Data'!E16 -> 18 | E7: ='Raw Data'!E17 -> 20 | F7: ='Raw Data'!E18 -> 23 | G7: ='Raw Data'!E19 -> 27
A8: Net PPE | B8: ='Raw Data'!F14 -> 145 | C8: ='Raw Data'!F15 -> 154 | D8: ='Raw Data'!F16 -> 168 | E8: ='Raw Data'!F17 -> 184 | F8: ='Raw Data'!F18 -> 207 | G8: ='Raw Data'!F19 -> 235
A9: Other Non-current Assets | B9: ='Raw Data'!G14 -> 38 | C9: ='Raw Data'!G15 -> 41 | D9: ='Raw Data'!G16 -> 45 | E9: ='Raw Data'!G17 -> 49 | F9: ='Raw Data'!G18 -> 55 | G9: ='Raw Data'!G19 -> 61
A10: Accounts Payable | B10: ='Raw Data'!H14 -> 54 | C10: ='Raw Data'!H15 -> 60 | D10: ='Raw Data'!H16 -> 67 | E10: ='Raw Data'!H17 -> 76 | F10: ='Raw Data'!H18 -> 89 | G10: ='Raw Data'!H19 -> 103
A11: Other Current Liabilities | B11: ='Raw Data'!I14 -> 31 | C11: ='Raw Data'!I15 -> 34 | D11: ='Raw Data'!I16 -> 39 | E11: ='Raw Data'!I17 -> 45 | F11: ='Raw Data'!I18 -> 52 | G11: ='Raw Data'!I19 -> 61
A12: Short-term Debt | B12: ='Raw Data'!J14 -> 24 | C12: ='Raw Data'!J15 -> 26 | D12: ='Raw Data'!J16 -> 29 | E12: ='Raw Data'!J17 -> 32 | F12: ='Raw Data'!J18 -> 36 | G12: ='Raw Data'!J19 -> 40
A13: Long-term Debt | B13: ='Raw Data'!K14 -> 92 | C13: ='Raw Data'!K15 -> 96 | D13: ='Raw Data'!K16 -> 101 | E13: ='Raw Data'!K17 -> 108 | F13: ='Raw Data'!K18 -> 116 | G13: ='Raw Data'!K19 -> 124
A14: Other Non-current Liabilities | B14: ='Raw Data'!L14 -> 19 | C14: ='Raw Data'!L15 -> 21 | D14: ='Raw Data'!L16 -> 23 | E14: ='Raw Data'!L17 -> 26 | F14: ='Raw Data'!L18 -> 29 | G14: ='Raw Data'!L19 -> 33
A15: Total Assets | B15: =SUM(B4:B9) -> 375 | C15: =SUM(C4:C9) -> 409 | D15: =SUM(D4:D9) -> 455 | E15: =SUM(E4:E9) -> 511 | F15: =SUM(F4:F9) -> 590 | G15: =SUM(G4:G9) -> 682
A16: Total Liabilities | B16: =SUM(B10:B14) -> 220 | C16: =SUM(C10:C14) -> 237 | D16: =SUM(D10:D14) -> 259 | E16: =SUM(E10:E14) -> 287 | F16: =SUM(F10:F14) -> 322 | G16: =SUM(G10:G14) -> 361
A17: Equity | B17: =B15-B16 -> 155 | C17: =C15-C16 -> 172 | D17: =D15-D16 -> 196 | E17: =E15-E16 -> 224 | F17: =F15-F16 -> 268 | G17: =G15-G16 -> 321
A18: Balance Check | B18: =B15-B16-B17 -> 0 | C18: =C15-C16-C17 -> 0 | D18: =D15-D16-D17 -> 0 | E18: =E15-E16-E17 -> 0 | F18: =F15-F16-F17 -> 0 | G18: =G15-G16-G17 -> 0
A19: Net Debt | B19: =B12+B13 -> 116 | C19: =C12+C13 -> 122 | D19: =D12+D13 -> 130 | E19: =E12+E13 -> 140 | F19: =F12+F13 -> 152 | G19: =G12+G13 -> 164

Sheet Cash Flow
A1: Cash Flow & Free Cash Flow
B3: 2021 | C3: 2022 | D3: 2023 | E3: 2024 | F3: 2025 | G3: 2026
A4: Net Profit | B4: ='Income Statement'!B14 -> 35 | C4: ='Income Statement'!C14 -> 40 | D4: ='Income Statement'!D14 -> 46 | E4: ='Income Statement'!E14 -> 60 | F4: ='Income Statement'!F14 -> 69 | G4: ='Income Statement'!G14 -> 85
A5: Depreciation | B5: ='Income Statement'!B9 -> 12 | C5: ='Income Statement'!C9 -> 13 | D5: ='Income Statement'!D9 -> 15 | E5: ='Income Statement'!E9 -> 17 | F5: ='Income Statement'!F9 -> 20 | G5: ='Income Statement'!G9 -> 23
A6: Change in Working Capital | B6: ='Raw Data'!C41 -> 8 | C6: ='Raw Data'!C42 -> 6 | D6: ='Raw Data'!C43 -> 9 | E6: ='Raw Data'!C44 -> 11 | F6: ='Raw Data'!C45 -> 14 | G6: ='Raw Data'!C46 -> 16
A7: Other Operating Cash Flow | B7: ='Raw Data'!D41 -> 4 | C7: ='Raw Data'!D42 -> 5 | D7: ='Raw Data'!D43 -> 6 | E7: ='Raw Data'!D44 -> 7 | F7: ='Raw Data'!D45 -> 9 | G7: ='Raw Data'!D46 -> 10
A8: Operating Cash Flow | B8: =SUM(B4:B7) -> 59 | C8: =SUM(C4:C7) -> 64 | D8: =SUM(D4:D7) -> 76 | E8: =SUM(E4:E7) -> 95 | F8: =SUM(F4:F7) -> 112 | G8: =SUM(G4:G7) -> 134
A9: Capex | B9: ='Raw Data'!B41 -> 22 | C9: ='Raw Data'!B42 -> 25 | D9: ='Raw Data'!B43 -> 28 | E9: ='Raw Data'!B44 -> 31 | F9: ='Raw Data'!B45 -> 38 | G9: ='Raw Data'!B46 -> 45
A10: Free Cash Flow | B10: =B8-B9 -> 37 | C10: =C8-C9 -> 39 | D10: =D8-D9 -> 48 | E10: =E8-E9 -> 64 | F10: =F8-F9 -> 74 | G10: =G8-G9 -> 89
A11: Debt Repayment | B11: ='Raw Data'!E41 -> 12 | C11: ='Raw Data'!E42 -> 10 | D11: ='Raw Data'!E43 -> 9 | E11: ='Raw Data'!E44 -> 8 | F11: ='Raw Data'!E45 -> 7 | G11: ='Raw Data'!E46 -> 6
A12: Cash Flow After Debt | B12: =B10-B11 -> 25 | C12: =C10-C11 -> 29 | D12: =D10-D11 -> 39 | E12: =E10-E11 -> 56 | F12: =F10-F11 -> 67 | G12: =G10-G11 -> 83

Sheet Ratios
A1: Financial Ratio Analysis
B3: 2021 | C3: 2022 | D3: 2023 | E3: 2024 | F3: 2025 | G3: 2026
A4: Revenue Growth | C4: ='Income Statement'!C4/'Income Statement'!B4-1 -> 0.10714286 | D4: ='Income Statement'!D4/'Income Statement'!C4-1 -> 0.11827957 | E4: ='Income Statement'!E4/'Income Statement'!D4-1 -> 0.13461538 | F4: ='Income Statement'!F4/'Income Statement'!E4-1 -> 0.1440678 | G4: ='Income Statement'!G4/'Income Statement'!F4-1 -> 0.15555556
A5: Gross Margin | B5: ='Income Statement'!B15 -> 0.35 | C5: ='Income Statement'!C15 -> 0.35483871 | D5: ='Income Statement'!D15 -> 0.35961538 | E5: ='Income Statement'!E15 -> 0.36949153 | F5: ='Income Statement'!F15 -> 0.37037037 | G5: ='Income Statement'!G15 -> 0.37435897
A6: EBITDA Margin | B6: ='Income Statement'!B16 -> 0.1547619 | C6: ='Income Statement'!C16 -> 0.15913978 | D6: ='Income Statement'!D16 -> 0.16538462 | E6: ='Income Statement'!E16 -> 0.17966102 | F6: ='Income Statement'!F16 -> 0.18518519 | G6: ='Income Statement'!G16 -> 0.19230769
A7: EBIT Margin | B7: ='Income Statement'!B17 -> 0.12619048 | C7: ='Income Statement'!C17 -> 0.1311828 | D7: ='Income Statement'!D17 -> 0.13653846 | E7: ='Income Statement'!E17 -> 0.15084746 | F7: ='Income Statement'!F17 -> 0.15555556 | G7: ='Income Statement'!G17 -> 0.16282051
A8: Net Profit Margin | B8: ='Income Statement'!B18 -> 0.083333333 | C8: ='Income Statement'!C18 -> 0.086021505 | D8: ='Income Statement'!D18 -> 0.088461538 | E8: ='Income Statement'!E18 -> 0.10169492 | F8: ='Income Statement'!F18 -> 0.10222222 | G8: ='Income Statement'!G18 -> 0.10897436
A9: Current Ratio | B9: =('Balance Sheet'!B4+'Balance Sheet'!B5+'Balance Sheet'!B6+'Balance Sheet'!B7)/('Balance Sheet'!B10+'Balance Sheet'!B11+'Balance Sheet'!B12) -> 1.7614679 | C9: =('Balance Sheet'!C4+'Balance Sheet'!C5+'Balance Sheet'!C6+'Balance Sheet'!C7)/('Balance Sheet'!C10+'Balance Sheet'!C11+'Balance Sheet'!C12) -> 1.7833333 | D9: =('Balance Sheet'!D4+'Balance Sheet'!D5+'Balance Sheet'!D6+'Balance Sheet'!D7)/('Balance Sheet'!D10+'Balance Sheet'!D11+'Balance Sheet'!D12) -> 1.7925926 | E9: =('Balance Sheet'!E4+'Balance Sheet'!E5+'Balance Sheet'!E6+'Balance Sheet'!E7)/('Balance Sheet'!E10+'Balance Sheet'!E11+'Balance Sheet'!E12) -> 1.8169935 | F9: =('Balance Sheet'!F4+'Balance Sheet'!F5+'Balance Sheet'!F6+'Balance Sheet'!F7)/('Balance Sheet'!F10+'Balance Sheet'!F11+'Balance Sheet'!F12) -> 1.8531073 | G9: =('Balance Sheet'!G4+'Balance Sheet'!G5+'Balance Sheet'!G6+'Balance Sheet'!G7)/('Balance Sheet'!G10+'Balance Sheet'!G11+'Balance Sheet'!G12) -> 1.8921569
A10: Debt / Equity | B10: =('Balance Sheet'!B12+'Balance Sheet'!B13+'Balance Sheet'!B14)/'Balance Sheet'!B17 -> 0.87096774 | C10: =('Balance Sheet'!C12+'Balance Sheet'!C13+'Balance Sheet'!C14)/'Balance Sheet'!C17 -> 0.83139535 | D10: =('Balance Sheet'!D12+'Balance Sheet'!D13+'Balance Sheet'!D14)/'Balance Sheet'!D17 -> 0.78061224 | E10: =('Balance Sheet'!E12+'Balance Sheet'!E13+'Balance Sheet'!E14)/'Balance Sheet'!E17 -> 0.74107143 | F10: =('Balance Sheet'!F12+'Balance Sheet'!F13+'Balance Sheet'!F14)/'Balance Sheet'!F17 -> 0.67537313 | G10: =('Balance Sheet'!G12+'Balance Sheet'!G13+'Balance Sheet'!G14)/'Balance Sheet'!G17 -> 0.61370717
A11: Debt / EBITDA | B11: =('Balance Sheet'!B12+'Balance Sheet'!B13+'Balance Sheet'!B14)/'Income Statement'!B8 -> 2.0769231 | C11: =('Balance Sheet'!C12+'Balance Sheet'!C13+'Balance Sheet'!C14)/'Income Statement'!C8 -> 1.9324324 | D11: =('Balance Sheet'!D12+'Balance Sheet'!D13+'Balance Sheet'!D14)/'Income Statement'!D8 -> 1.7790698 | E11: =('Balance Sheet'!E12+'Balance Sheet'!E13+'Balance Sheet'!E14)/'Income Statement'!E8 -> 1.5660377 | F11: =('Balance Sheet'!F12+'Balance Sheet'!F13+'Balance Sheet'!F14)/'Income Statement'!F8 -> 1.448 | G11: =('Balance Sheet'!G12+'Balance Sheet'!G13+'Balance Sheet'!G14)/'Income Statement'!G8 -> 1.3133333
A12: Interest Coverage | B12: ='Income Statement'!B10/'Income Statement'!B11 -> 5.3 | C12: ='Income Statement'!C10/'Income Statement'!C11 -> 5.5454545 | D12: ='Income Statement'!D10/'Income Statement'!D11 -> 5.9166667 | E12: ='Income Statement'!E10/'Income Statement'!E11 -> 6.8461538 | F12: ='Income Statement'!F10/'Income Statement'!F11 -> 7 | G12: ='Income Statement'!G10/'Income Statement'!G11 -> 7.4705882
A13: ROA | B13: ='Income Statement'!B14/'Balance Sheet'!B15 -> 0.093333333 | C13: ='Income Statement'!C14/'Balance Sheet'!C15 -> 0.097799511 | D13: ='Income Statement'!D14/'Balance Sheet'!D15 -> 0.1010989 | E13: ='Income Statement'!E14/'Balance Sheet'!E15 -> 0.11741683 | F13: ='Income Statement'!F14/'Balance Sheet'!F15 -> 0.11694915 | G13: ='Income Statement'!G14/'Balance Sheet'!G15 -> 0.12463343
A14: ROE | B14: ='Income Statement'!B14/'Balance Sheet'!B17 -> 0.22580645 | C14: ='Income Statement'!C14/'Balance Sheet'!C17 -> 0.23255814 | D14: ='Income Statement'!D14/'Balance Sheet'!D17 -> 0.23469388 | E14: ='Income Statement'!E14/'Balance Sheet'!E17 -> 0.26785714 | F14: ='Income Statement'!F14/'Balance Sheet'!F17 -> 0.25746269 | G14: ='Income Statement'!G14/'Balance Sheet'!G17 -> 0.26479751
A15: FCF Margin | B15: ='Cash Flow'!B10/'Income Statement'!B4 -> 0.088095238 | C15: ='Cash Flow'!C10/'Income Statement'!C4 -> 0.083870968 | D15: ='Cash Flow'!D10/'Income Statement'!D4 -> 0.092307692 | E15: ='Cash Flow'!E10/'Income Statement'!E4 -> 0.10847458 | F15: ='Cash Flow'!F10/'Income Statement'!F4 -> 0.10962963 | G15: ='Cash Flow'!G10/'Income Statement'!G4 -> 0.11410256

Sheet Revenue Analysis
A1: Revenue Analysis
B3: 2021 | C3: 2022 | D3: 2023 | E3: 2024 | F3: 2025 | G3: 2026
A4: Industrial Automation | B4: ='Raw Data'!B23 -> 170 | C4: ='Raw Data'!B24 -> 190 | D4: ='Raw Data'!B25 -> 214 | E4: ='Raw Data'!B26 -> 244 | F4: ='Raw Data'!B27 -> 281 | G4: ='Raw Data'!B28 -> 327
A5: Motion Control | B5: ='Raw Data'!C23 -> 135 | C5: ='Raw Data'!C24 -> 149 | D5: ='Raw Data'!C25 -> 166 | E5: ='Raw Data'!C26 -> 188 | F5: ='Raw Data'!C27 -> 215 | G5: ='Raw Data'!C28 -> 248
A6: Service & Spares | B6: ='Raw Data'!D23 -> 115 | C6: ='Raw Data'!D24 -> 126 | D6: ='Raw Data'!D25 -> 140 | E6: ='Raw Data'!D26 -> 158 | F6: ='Raw Data'!D27 -> 179 | G6: ='Raw Data'!D28 -> 205
A7: Total Segment Revenue | B7: =SUM(B4:B6) -> 420 | C7: =SUM(C4:C6) -> 465 | D7: =SUM(D4:D6) -> 520 | E7: =SUM(E4:E6) -> 590 | F7: =SUM(F4:F6) -> 675 | G7: =SUM(G4:G6) -> 780
A8: Segment Mix – Automation | B8: =B4/B7 -> 0.4047619 | C8: =C4/C7 -> 0.40860215 | D8: =D4/D7 -> 0.41153846 | E8: =E4/E7 -> 0.41355932 | F8: =F4/F7 -> 0.4162963 | G8: =G4/G7 -> 0.41923077
A9: Segment Mix – Motion | B9: =B5/B7 -> 0.32142857 | C9: =C5/C7 -> 0.32043011 | D9: =D5/D7 -> 0.31923077 | E9: =E5/E7 -> 0.31864407 | F9: =F5/F7 -> 0.31851852 | G9: =G5/G7 -> 0.31794872
A10: Segment Mix – Service | B10: =B6/B7 -> 0.27380952 | C10: =C6/C7 -> 0.27096774 | D10: =D6/D7 -> 0.26923077 | E10: =E6/E7 -> 0.26779661 | F10: =F6/F7 -> 0.26518519 | G10: =G6/G7 -> 0.26282051
A13: Revenue by Geography
B14: 2021 | C14: 2022 | D14: 2023 | E14: 2024 | F14: 2025 | G14: 2026
A15: India | B15: ='Raw Data'!B32 -> 300 | C15: ='Raw Data'!B33 -> 330 | D15: ='Raw Data'!B34 -> 370 | E15: ='Raw Data'!B35 -> 420 | F15: ='Raw Data'!B36 -> 485 | G15: ='Raw Data'!B37 -> 560
A16: Middle East | B16: ='Raw Data'!C32 -> 55 | C16: ='Raw Data'!C33 -> 61 | D16: ='Raw Data'!C34 -> 68 | E16: ='Raw Data'!C35 -> 76 | F16: ='Raw Data'!C36 -> 86 | G16: ='Raw Data'!C37 -> 98
A17: Southeast Asia | B17: ='Raw Data'!D32 -> 40 | C17: ='Raw Data'!D33 -> 44 | D17: ='Raw Data'!D34 -> 48 | E17: ='Raw Data'!D35 -> 54 | F17: ='Raw Data'!D36 -> 61 | G17: ='Raw Data'!D37 -> 70
A18: Europe | B18: ='Raw Data'!E32 -> 25 | C18: ='Raw Data'!E33 -> 30 | D18: ='Raw Data'!E34 -> 34 | E18: ='Raw Data'!E35 -> 40 | F18: ='Raw Data'!E36 -> 43 | G18: ='Raw Data'!E37 -> 52
A19: Total Geographic Revenue | B19: =SUM(B15:B18) -> 420 | C19: =SUM(C15:C18) -> 465 | D19: =SUM(D15:D18) -> 520 | E19: =SUM(E15:E18) -> 590 | F19: =SUM(F15:F18) -> 675 | G19: =SUM(G15:G18) -> 780
A20: Mix – India | B20: =B15/B19 -> 0.71428571 | C20: =C15/C19 -> 0.70967742 | D20: =D15/D19 -> 0.71153846 | E20: =E15/E19 -> 0.71186441 | F20: =F15/F19 -> 0.71851852 | G20: =G15/G19 -> 0.71794872
A21: Mix – Middle East | B21: =B16/B19 -> 0.13095238 | C21: =C16/C19 -> 0.1311828 | D21: =D16/D19 -> 0.13076923 | E21: =E16/E19 -> 0.12881356 | F21: =F16/F19 -> 0.12740741 | G21: =G16/G19 -> 0.12564103
A22: Mix – Southeast Asia | B22: =B17/B19 -> 0.095238095 | C22: =C17/C19 -> 0.094623656 | D22: =D17/D19 -> 0.092307692 | E22: =E17/E19 -> 0.091525424 | F22: =F17/F19 -> 0.09037037 | G22: =G17/G19 -> 0.08974359
A23: Mix – Europe | B23: =B18/B19 -> 0.05952381 | C23: =C18/C19 -> 0.064516129 | D23: =D18/D19 -> 0.065384615 | E23: =E18/E19 -> 0.06779661 | F23: =F18/F19 -> 0.063703704 | G23: =G18/G19 -> 0.066666667

Sheet Working Capital
A1: Working Capital Analysis
B3: 2021 | C3: 2022 | D3: 2023 | E3: 2024 | F3: 2025 | G3: 2026
A4: DSO (days) | B4: ='Balance Sheet'!B5/'Income Statement'!B4*365 -> 59.095238 | C4: ='Balance Sheet'!C5/'Income Statement'!C4*365 -> 58.870968 | D4: ='Balance Sheet'!D5/'Income Statement'!D4*365 -> 58.961538 | E4: ='Balance Sheet'!E5/'Income Statement'!E4*365 -> 59.389831 | F4: ='Balance Sheet'!F5/'Income Statement'!F4*365 -> 60.022222 | G4: ='Balance Sheet'!G5/'Income Statement'!G4*365 -> 59.897436
A5: DIO (days) | B5: ='Balance Sheet'!B6/'Income Statement'!B5*365 -> 96.263736 | C5: ='Balance Sheet'!C6/'Income Statement'!C5*365 -> 96.116667 | D5: ='Balance Sheet'!D6/'Income Statement'!D5*365 -> 96.456456 | E5: ='Balance Sheet'!E6/'Income Statement'!E5*365 -> 99.099462 | F5: ='Balance Sheet'!F6/'Income Statement'!F5*365 -> 101.34118 | G5: ='Balance Sheet'!G6/'Income Statement'!G5*365 -> 101.72131
A6: DPO (days) | B6: ='Balance Sheet'!B10/'Income Statement'!B5*365 -> 72.197802 | C6: ='Balance Sheet'!C10/'Income Statement'!C5*365 -> 73 | D6: ='Balance Sheet'!D10/'Income Statement'!D5*365 -> 73.438438 | E6: ='Balance Sheet'!E10/'Income Statement'!E5*365 -> 74.569892 | F6: ='Balance Sheet'!F10/'Income Statement'!F5*365 -> 76.435294 | G6: ='Balance Sheet'!G10/'Income Statement'!G5*365 -> 77.038934
A7: Cash Conversion Cycle | B7: =B4+B5-B6 -> 83.161172 | C7: =C4+C5-C6 -> 81.987634 | D7: =D4+D5-D6 -> 81.979556 | E7: =E4+E5-E6 -> 83.9194 | F7: =F4+F5-F6 -> 84.928105 | G7: =G4+G5-G6 -> 84.579813
A8: Working Capital | B8: =('Balance Sheet'!B5+'Balance Sheet'!B6)-('Balance Sheet'!B10) -> 86 | C8: =('Balance Sheet'!C5+'Balance Sheet'!C6)-('Balance Sheet'!C10) -> 94 | D8: =('Balance Sheet'!D5+'Balance Sheet'!D6)-('Balance Sheet'!D10) -> 105 | E8: =('Balance Sheet'!E5+'Balance Sheet'!E6)-('Balance Sheet'!E10) -> 121 | F8: =('Balance Sheet'!F5+'Balance Sheet'!F6)-('Balance Sheet'!F10) -> 140 | G8: =('Balance Sheet'!G5+'Balance Sheet'!G6)-('Balance Sheet'!G10) -> 161
A9: Working Capital / Revenue | B9: =B8/'Income Statement'!B4 -> 0.2047619 | C9: =C8/'Income Statement'!C4 -> 0.20215054 | D9: =D8/'Income Statement'!D4 -> 0.20192308 | E9: =E8/'Income Statement'!E4 -> 0.20508475 | F9: =F8/'Income Statement'!F4 -> 0.20740741 | G9: =G8/'Income Statement'!G4 -> 0.20641026

Sheet Forecast
A1: Base-Case Forecast (₹ crore)
B3: 2021 | C3: 2022 | D3: 2023 | E3: 2024 | F3: 2025 | G3: 2026 | H3: 2027 | I3: 2028 | J3: 2029
A4: Revenue | B4: ='Income Statement'!B4 -> 420 | C4: ='Income Statement'!C4 -> 465 | D4: ='Income Statement'!D4 -> 520 | E4: ='Income Statement'!E4 -> 590 | F4: ='Income Statement'!F4 -> 675 | G4: ='Income Statement'!G4 -> 780 | H4: =G4*(1+H21) -> 858 | I4: =H4*(1+I21) -> 935.22 | J4: =I4*(1+J21) -> 1010.0376
A5: Growth | C5: =C4/B4-1 -> 0.10714286 | D5: =D4/C4-1 -> 0.11827957 | E5: =E4/D4-1 -> 0.13461538 | F5: =F4/E4-1 -> 0.1440678 | G5: =G4/F4-1 -> 0.15555556 | H5: =H21 -> 0.1 | I5: =I21 -> 0.09 | J5: =J21 -> 0.08
A6: COGS % Revenue | B6: ='Income Statement'!B5/'Income Statement'!B4 -> 0.65 | C6: ='Income Statement'!C5/'Income Statement'!C4 -> 0.64516129 | D6: ='Income Statement'!D5/'Income Statement'!D4 -> 0.64038462 | E6: ='Income Statement'!E5/'Income Statement'!E4 -> 0.63050847 | F6: ='Income Statement'!F5/'Income Statement'!F4 -> 0.62962963 | G6: ='Income Statement'!G5/'Income Statement'!G4 -> 0.62564103 | H6: =H22 -> 0.625 | I6: =I22 -> 0.62 | J6: =J22 -> 0.615
A7: Operating Expenses % Revenue | B7: ='Income Statement'!B7/'Income Statement'!B4 -> 0.1952381 | C7: ='Income Statement'!C7/'Income Statement'!C4 -> 0.19569892 | D7: ='Income Statement'!D7/'Income Statement'!D4 -> 0.19423077 | E7: ='Income Statement'!E7/'Income Statement'!E4 -> 0.18983051 | F7: ='Income Statement'!F7/'Income Statement'!F4 -> 0.18518519 | G7: ='Income Statement'!G7/'Income Statement'!G4 -> 0.18205128 | H7: =H23 -> 0.18 | I7: =I23 -> 0.178 | J7: =J23 -> 0.176
A8: Depreciation % Revenue | B8: ='Income Statement'!B9/'Income Statement'!B4 -> 0.028571429 | C8: ='Income Statement'!C9/'Income Statement'!C4 -> 0.027956989 | D8: ='Income Statement'!D9/'Income Statement'!D4 -> 0.028846154 | E8: ='Income Statement'!E9/'Income Statement'!E4 -> 0.028813559 | F8: ='Income Statement'!F9/'Income Statement'!F4 -> 0.02962963 | G8: ='Income Statement'!G9/'Income Statement'!G4 -> 0.029487179 | H8: =H24 -> 0.029 | I8: =I24 -> 0.028 | J8: =J24 -> 0.028
A9: EBITDA | B9: ='Income Statement'!B8 -> 65 | C9: ='Income Statement'!C8 -> 74 | D9: ='Income Statement'!D8 -> 86 | E9: ='Income Statement'!E8 -> 106 | F9: ='Income Statement'!F8 -> 125 | G9: ='Income Statement'!G8 -> 150 | H9: =H4*(1-H6-H7) -> 167.31 | I9: =I4*(1-I6-I7) -> 188.91444 | J9: =J4*(1-J6-J7) -> 211.09786
A10: EBIT | B10: ='Income Statement'!B10 -> 53 | C10: ='Income Statement'!C10 -> 61 | D10: ='Income Statement'!D10 -> 71 | E10: ='Income Statement'!E10 -> 89 | F10: ='Income Statement'!F10 -> 105 | G10: ='Income Statement'!G10 -> 127 | H10: =H9-H4*H8 -> 142.428 | I10: =I9-I4*I8 -> 162.72828 | J10: =J9-J4*J8 -> 182.81681
A11: Interest Expense | B11: ='Income Statement'!B11 -> 10 | C11: ='Income Statement'!C11 -> 11 | D11: ='Income Statement'!D11 -> 12 | E11: ='Income Statement'!E11 -> 13 | F11: ='Income Statement'!F11 -> 15 | G11: ='Income Statement'!G11 -> 17 | H11: =H25 -> 18 | I11: =I25 -> 19 | J11: =J25 -> 20
A12: PBT | B12: ='Income Statement'!B12 -> 43 | C12: ='Income Statement'!C12 -> 50 | D12: ='Income Statement'!D12 -> 59 | E12: ='Income Statement'!E12 -> 76 | F12: ='Income Statement'!F12 -> 90 | G12: ='Income Statement'!G12 -> 110 | H12: =H10-H11 -> 124.428 | I12: =I10-I11 -> 143.72828 | J12: =J10-J11 -> 162.81681
A13: Tax Rate | B13: ='Income Statement'!B13/'Income Statement'!B12 -> 0.18604651 | C13: ='Income Statement'!C13/'Income Statement'!C12 -> 0.2 | D13: ='Income Statement'!D13/'Income Statement'!D12 -> 0.22033898 | E13: ='Income Statement'!E13/'Income Statement'!E12 -> 0.21052632 | F13: ='Income Statement'!F13/'Income Statement'!F12 -> 0.23333333 | G13: ='Income Statement'!G13/'Income Statement'!G12 -> 0.22727273 | H13: =H26 -> 0.25 | I13: =I26 -> 0.25 | J13: =J26 -> 0.25
A14: Net Profit | B14: ='Income Statement'!B14 -> 35 | C14: ='Income Statement'!C14 -> 40 | D14: ='Income Statement'!D14 -> 46 | E14: ='Income Statement'!E14 -> 60 | F14: ='Income Statement'!F14 -> 69 | G14: ='Income Statement'!G14 -> 85 | H14: =H12*(1-H13) -> 93.321 | I14: =I12*(1-I13) -> 107.79621 | J14: =J12*(1-J13) -> 122.1126
A15: Capex % Revenue | B15: ='Cash Flow'!B9/'Income Statement'!B4 -> 0.052380952 | C15: ='Cash Flow'!C9/'Income Statement'!C4 -> 0.053763441 | D15: ='Cash Flow'!D9/'Income Statement'!D4 -> 0.053846154 | E15: ='Cash Flow'!E9/'Income Statement'!E4 -> 0.052542373 | F15: ='Cash Flow'!F9/'Income Statement'!F4 -> 0.056296296 | G15: ='Cash Flow'!G9/'Income Statement'!G4 -> 0.057692308 | H15: =H27 -> 0.055 | I15: =I27 -> 0.052 | J15: =J27 -> 0.05
A16: Change in WC % Revenue | B16: ='Cash Flow'!B6/'Income Statement'!B4 -> 0.019047619 | C16: ='Cash Flow'!C6/'Income Statement'!C4 -> 0.012903226 | D16: ='Cash Flow'!D6/'Income Statement'!D4 -> 0.017307692 | E16: ='Cash Flow'!E6/'Income Statement'!E4 -> 0.018644068 | F16: ='Cash Flow'!F6/'Income Statement'!F4 -> 0.020740741 | G16: ='Cash Flow'!G6/'Income Statement'!G4 -> 0.020512821 | H16: =H28 -> 0.02 | I16: =I28 -> 0.019 | J16: =J28 -> 0.018
A17: Free Cash Flow | B17: ='Cash Flow'!B10 -> 37 | C17: ='Cash Flow'!C10 -> 39 | D17: ='Cash Flow'!D10 -> 48 | E17: ='Cash Flow'!E10 -> 64 | F17: ='Cash Flow'!F10 -> 74 | G17: ='Cash Flow'!G10 -> 89 | H17: =H14+H4*H8-H4*H15-H4*H16 -> 53.853 | I17: =I14+I4*I8-I4*I15-I4*I16 -> 67.58175 | J17: =J14+J4*J8-J4*J15-J4*J16 -> 81.7111
A20: Forecast assumptions
A21: Revenue Growth | H21: 0.1 | I21: 0.09 | J21: 0.08
A22: COGS % Revenue | H22: 0.625 | I22: 0.62 | J22: 0.615
A23: OpEx % Revenue | H23: 0.18 | I23: 0.178 | J23: 0.176
A24: Depreciation % Revenue | H24: 0.029 | I24: 0.028 | J24: 0.028
A25: Interest Expense | H25: 18 | I25: 19 | J25: 20
A26: Tax Rate | H26: 0.25 | I26: 0.25 | J26: 0.25
A27: Capex % Revenue | H27: 0.055 | I27: 0.052 | J27: 0.05
A28: Change in WC % Revenue | H28: 0.02 | I28: 0.019 | J28: 0.018

Sheet Scenario Analysis
A1: Scenario Analysis — Bull / Base / Bear Case
A3: Scenario Deltas vs. Base-Case Forecast (applied uniformly, FY2027–FY2029)
A4: Bull Case: Revenue Growth Δ (pts) | B4: 0.02
A5: Bull Case: COGS % Δ (pts, − = margin gain) | B5: -0.01
A6: Bear Case: Revenue Growth Δ (pts) | B6: -0.02
A7: Bear Case: COGS % Δ (pts, + = margin pressure) | B7: 0.01
A8: All other drivers (OpEx %, Depreciation %, Interest Expense, Tax Rate, Capex %, Change in WC %) held at Base-Case levels in every scenario.
A10: Base Case (linked from Forecast tab)
B11: 2027 | C11: 2028 | D11: 2029
A12: Revenue | B12: =Forecast!H4 -> 858 | C12: =Forecast!I4 -> 935.22 | D12: =Forecast!J4 -> 1010.0376
A13: EBITDA | B13: =Forecast!H9 -> 167.31 | C13: =Forecast!I9 -> 188.91444 | D13: =Forecast!J9 -> 211.09786
A14: EBIT | B14: =Forecast!H10 -> 142.428 | C14: =Forecast!I10 -> 162.72828 | D14: =Forecast!J10 -> 182.81681
A15: Net Profit | B15: =Forecast!H14 -> 93.321 | C15: =Forecast!I14 -> 107.79621 | D15: =Forecast!J14 -> 122.1126
A16: Free Cash Flow | B16: =Forecast!H17 -> 53.853 | C16: =Forecast!I17 -> 67.58175 | D16: =Forecast!J17 -> 81.7111
A18: Bull Case
B19: 2027 | C19: 2028 | D19: 2029
A20: Revenue Growth | B20: =Forecast!H21+$B$4 -> 0.12 | C20: =Forecast!I21+$B$4 -> 0.11 | D20: =Forecast!J21+$B$4 -> 0.1
A21: Revenue | B21: ='Income Statement'!G4*(1+B20) -> 873.6 | C21: =B21*(1+C20) -> 969.696 | D21: =C21*(1+D20) -> 1066.6656
A22: COGS % Revenue | B22: =Forecast!H22+$B$5 -> 0.615 | C22: =Forecast!I22+$B$5 -> 0.61 | D22: =Forecast!J22+$B$5 -> 0.605
A23: EBITDA | B23: =B21*(1-B22-Forecast!H23) -> 179.088 | C23: =C21*(1-C22-Forecast!I23) -> 205.57555 | D23: =D21*(1-D22-Forecast!J23) -> 233.59977
A24: EBIT | B24: =B23-B21*Forecast!H24 -> 153.7536 | C24: =C23-C21*Forecast!I24 -> 178.42406 | D24: =D23-D21*Forecast!J24 -> 203.73313
A25: PBT | B25: =B24-Forecast!H25 -> 135.7536 | C25: =C24-Forecast!I25 -> 159.42406 | D25: =D24-Forecast!J25 -> 183.73313
A26: Net Profit | B26: =B25*(1-Forecast!H26) -> 101.8152 | C26: =C25*(1-Forecast!I26) -> 119.56805 | D26: =D25*(1-Forecast!J26) -> 137.79985
A27: Free Cash Flow | B27: =B26+B21*Forecast!H24-B21*Forecast!H27-B21*Forecast!H28 -> 61.6296 | C27: =C26+C21*Forecast!I24-C21*Forecast!I27-C21*Forecast!I28 -> 77.87112 | D27: =D26+D21*Forecast!J24-D21*Forecast!J27-D21*Forecast!J28 -> 95.133223
A29: Bear Case
B30: 2027 | C30: 2028 | D30: 2029
A31: Revenue Growth | B31: =Forecast!H21+$B$6 -> 0.08 | C31: =Forecast!I21+$B$6 -> 0.07 | D31: =Forecast!J21+$B$6 -> 0.06
A32: Revenue | B32: ='Income Statement'!G4*(1+B31) -> 842.4 | C32: =B32*(1+C31) -> 901.368 | D32: =C32*(1+D31) -> 955.45008
A33: COGS % Revenue | B33: =Forecast!H22+$B$7 -> 0.635 | C33: =Forecast!I22+$B$7 -> 0.63 | D33: =Forecast!J22+$B$7 -> 0.625
A34: EBITDA | B34: =B32*(1-B33-Forecast!H23) -> 155.844 | C34: =C32*(1-C33-Forecast!I23) -> 173.06266 | D34: =D32*(1-D33-Forecast!J23) -> 190.13457
A35: EBIT | B35: =B34-B32*Forecast!H24 -> 131.4144 | C35: =C34-C32*Forecast!I24 -> 147.82435 | D35: =D34-D32*Forecast!J24 -> 163.38196
A36: PBT | B36: =B35-Forecast!H25 -> 113.4144 | C36: =C35-Forecast!I25 -> 128.82435 | D36: =D35-Forecast!J25 -> 143.38196
A37: Net Profit | B37: =B36*(1-Forecast!H26) -> 85.0608 | C37: =C36*(1-Forecast!I26) -> 96.618264 | D37: =D36*(1-Forecast!J26) -> 107.53647
A38: Free Cash Flow | B38: =B37+B32*Forecast!H24-B32*Forecast!H27-B32*Forecast!H28 -> 46.3104 | C38: =C37+C32*Forecast!I24-C32*Forecast!I27-C32*Forecast!I28 -> 57.85944 | D38: =D37+D32*Forecast!J24-D32*Forecast!J27-D32*Forecast!J28 -> 69.31847
A40: Scenario Valuation Summary — FY2029E (using DCF tab WACC & Terminal Growth)
A41: Scenario | B41: FY2029 Revenue | C41: FY2029 EBITDA | D41: EBITDA Margin | E41: FY2029 Net Profit | F41: Net Margin | G41: Implied Value/Share (₹) | H41: Δ vs Base
A42: Bear | B42: =D32 -> 955.45008 | C42: =D34 -> 190.13457 | D42: =C42/B42 -> 0.199 | E42: =D37 -> 107.53647 | F42: =E42/B42 -> 0.11255059 | G42: =((B38/(1+DCF!$B$4)^1)+(C38/(1+DCF!$B$4)^2)+(D38/(1+DCF!$B$4)^3)+((D38*(1+DCF!$B$5))/(DCF!$B$4-DCF!$B$5))/(1+DCF!$B$4)^3-DCF!$B$6)/DCF!$B$7 -> 65.29646 | H42: =G42/$G$43-1 -> -0.18160629
A43: Base | B43: =D12 -> 1010.0376 | C43: =D13 -> 211.09786 | D43: =C43/B43 -> 0.209 | E43: =D15 -> 122.1126 | F43: =E43/B43 -> 0.12089907 | G43: =((B16/(1+DCF!$B$4)^1)+(C16/(1+DCF!$B$4)^2)+(D16/(1+DCF!$B$4)^3)+((D16*(1+DCF!$B$5))/(DCF!$B$4-DCF!$B$5))/(1+DCF!$B$4)^3-DCF!$B$6)/DCF!$B$7 -> 79.786122 | H43: =G43/$G$43-1 -> 0
A44: Bull | B44: =D21 -> 1066.6656 | C44: =D23 -> 233.59977 | D44: =C44/B44 -> 0.219 | E44: =D26 -> 137.79985 | F44: =E44/B44 -> 0.12918749 | G44: =((B27/(1+DCF!$B$4)^1)+(C27/(1+DCF!$B$4)^2)+(D27/(1+DCF!$B$4)^3)+((D27*(1+DCF!$B$5))/(DCF!$B$4-DCF!$B$5))/(1+DCF!$B$4)^3-DCF!$B$6)/DCF!$B$7 -> 95.425005 | H44: =G44/$G$43-1 -> 0.19601008
A46: Bull/Bear deltas affect revenue growth and gross-margin trajectory only; all other drivers held at Base-Case levels (see note above).

Sheet DCF
A1: DCF Valuation Framework
A3: Assumptions
A4: WACC | B4: =B35 -> 0.11630103
A5: Terminal Growth | B5: 0.04
A6: Net Debt (latest historical) | B6: ='Balance Sheet'!G19 -> 164
A7: Shares Outstanding (crore) | B7: 10
A10: Forecast FCF
B11: 2027 | C11: 2028 | D11: 2029
A12: FCF | B12: =Forecast!H17 -> 53.853 | C12: =Forecast!I17 -> 67.58175 | D12: =Forecast!J17 -> 81.7111
A13: Discount Factor | B13: =1/(1+$B$4)^1 -> 0.89581571 | C13: =1/(1+$B$4)^2 -> 0.80248579 | D13: =1/(1+$B$4)^3 -> 0.71887937
A14: PV of FCF | B14: =B12*B13 -> 48.242363 | C14: =C12*C13 -> 54.233394 | D14: =D12*D13 -> 58.740424
A16: Terminal Value | B16: =D12*(1+$B$5)/($B$4-$B$5) -> 1113.7404
A17: PV of Terminal Value | B17: =B16*D13 -> 800.64503
A18: Enterprise Value | B18: =SUM(B14:D14)+B17 -> 961.86122
A19: Less: Net Debt | B19: =B6 -> 164
A20: Equity Value | B20: =B18-B19 -> 797.86122
A21: Implied Value / Share | B21: =B20/B7 -> 79.786122
A23: Cost of Capital Build-Up (CAPM)
A24: Risk-Free Rate (10Y G-Sec, illustrative) | B24: 0.07
A25: Levered Beta (illustrative, industrial peers) | B25: 1.1
A26: Equity Risk Premium (illustrative) | B26: 0.06
A27: Cost of Equity (Ke = Rf + β × ERP) | B27: =B24+B25*B26 -> 0.136
A28: Pre-tax Cost of Debt (Interest Exp. ÷ Total Debt, FY26) | B28: ='Income Statement'!G11/('Balance Sheet'!G12+'Balance Sheet'!G13) -> 0.10365854
A29: Effective Tax Rate (Forecast assumption) | B29: =Forecast!H26 -> 0.25
A30: After-tax Cost of Debt | B30: =B28*(1-B29) -> 0.077743902
A31: Equity (Book Value, FY26 — proxy for weights) | B31: ='Balance Sheet'!G17 -> 321
A32: Total Debt (FY2026) | B32: ='Balance Sheet'!G12+'Balance Sheet'!G13 -> 164
A33: Weight of Equity | B33: =B31/(B31+B32) -> 0.66185567
A34: Weight of Debt | B34: =B32/(B31+B32) -> 0.33814433
A35: WACC (Computed) | B35: =B33*B27+B34*B30 -> 0.11630103
A38: Sensitivity Analysis — Implied Value per Share (₹)
A39: Rows = WACC · Columns = Terminal Growth Rate (± around base case)
A40: WACC \ Terminal g | B40: =$B$5-0.01 -> 0.03 | C40: =$B$5-0.005 -> 0.035 | D40: =$B$5 -> 0.04 | E40: =$B$5+0.005 -> 0.045 | F40: =$B$5+0.01 -> 0.05
A41: =$B$4-0.01 -> 0.10630103 | B41: =(($B$12/(1+$A41)^1)+($C$12/(1+$A41)^2)+($D$12/(1+$A41)^3)+(($D$12*(1+B$40))/($A41-B$40))/(1+$A41)^3-$B$6)/$B$7 -> 81.488857 | C41: =(($B$12/(1+$A41)^1)+($C$12/(1+$A41)^2)+($D$12/(1+$A41)^3)+(($D$12*(1+C$40))/($A41-C$40))/(1+$A41)^3-$B$6)/$B$7 -> 87.624756 | D41: =(($B$12/(1+$A41)^1)+($C$12/(1+$A41)^2)+($D$12/(1+$A41)^3)+(($D$12*(1+D$40))/($A41-D$40))/(1+$A41)^3-$B$6)/$B$7 -> 94.686116 | E41: =(($B$12/(1+$A41)^1)+($C$12/(1+$A41)^2)+($D$12/(1+$A41)^3)+(($D$12*(1+E$40))/($A41-E$40))/(1+$A41)^3-$B$6)/$B$7 -> 102.89939 | F41: =(($B$12/(1+$A41)^1)+($C$12/(1+$A41)^2)+($D$12/(1+$A41)^3)+(($D$12*(1+F$40))/($A41-F$40))/(1+$A41)^3-$B$6)/$B$7 -> 112.57148
A42: =$B$4-0.005 -> 0.11130103 | B42: =(($B$12/(1+$A42)^1)+($C$12/(1+$A42)^2)+($D$12/(1+$A42)^3)+(($D$12*(1+B$40))/($A42-B$40))/(1+$A42)^3-$B$6)/$B$7 -> 75.298921 | C42: =(($B$12/(1+$A42)^1)+($C$12/(1+$A42)^2)+($D$12/(1+$A42)^3)+(($D$12*(1+C$40))/($A42-C$40))/(1+$A42)^3-$B$6)/$B$7 -> 80.631793 | D42: =(($B$12/(1+$A42)^1)+($C$12/(1+$A42)^2)+($D$12/(1+$A42)^3)+(($D$12*(1+D$40))/($A42-D$40))/(1+$A42)^3-$B$6)/$B$7 -> 86.712602 | E42: =(($B$12/(1+$A42)^1)+($C$12/(1+$A42)^2)+($D$12/(1+$A42)^3)+(($D$12*(1+E$40))/($A42-E$40))/(1+$A42)^3-$B$6)/$B$7 -> 93.710564 | F42: =(($B$12/(1+$A42)^1)+($C$12/(1+$A42)^2)+($D$12/(1+$A42)^3)+(($D$12*(1+F$40))/($A42-F$40))/(1+$A42)^3-$B$6)/$B$7 -> 101.8501
A43: =$B$4 -> 0.11630103 | B43: =(($B$12/(1+$A43)^1)+($C$12/(1+$A43)^2)+($D$12/(1+$A43)^3)+(($D$12*(1+B$40))/($A43-B$40))/(1+$A43)^3-$B$6)/$B$7 -> 69.828124 | C43: =(($B$12/(1+$A43)^1)+($C$12/(1+$A43)^2)+($D$12/(1+$A43)^3)+(($D$12*(1+C$40))/($A43-C$40))/(1+$A43)^3-$B$6)/$B$7 -> 74.500915 | D43: =(($B$12/(1+$A43)^1)+($C$12/(1+$A43)^2)+($D$12/(1+$A43)^3)+(($D$12*(1+D$40))/($A43-D$40))/(1+$A43)^3-$B$6)/$B$7 -> 79.786122 | E43: =(($B$12/(1+$A43)^1)+($C$12/(1+$A43)^2)+($D$12/(1+$A43)^3)+(($D$12*(1+E$40))/($A43-E$40))/(1+$A43)^3-$B$6)/$B$7 -> 85.81258 | F43: =(($B$12/(1+$A43)^1)+($C$12/(1+$A43)^2)+($D$12/(1+$A43)^3)+(($D$12*(1+F$40))/($A43-F$40))/(1+$A43)^3-$B$6)/$B$7 -> 92.747993
A44: =$B$4+0.005 -> 0.12130103 | B44: =(($B$12/(1+$A44)^1)+($C$12/(1+$A44)^2)+($D$12/(1+$A44)^3)+(($D$12*(1+B$40))/($A44-B$40))/(1+$A44)^3-$B$6)/$B$7 -> 64.958289 | C44: =(($B$12/(1+$A44)^1)+($C$12/(1+$A44)^2)+($D$12/(1+$A44)^3)+(($D$12*(1+C$40))/($A44-C$40))/(1+$A44)^3-$B$6)/$B$7 -> 69.082254 | D44: =(($B$12/(1+$A44)^1)+($C$12/(1+$A44)^2)+($D$12/(1+$A44)^3)+(($D$12*(1+D$40))/($A44-D$40))/(1+$A44)^3-$B$6)/$B$7 -> 73.713465 | E44: =(($B$12/(1+$A44)^1)+($C$12/(1+$A44)^2)+($D$12/(1+$A44)^3)+(($D$12*(1+E$40))/($A44-E$40))/(1+$A44)^3-$B$6)/$B$7 -> 78.951642 | F44: =(($B$12/(1+$A44)^1)+($C$12/(1+$A44)^2)+($D$12/(1+$A44)^3)+(($D$12*(1+F$40))/($A44-F$40))/(1+$A44)^3-$B$6)/$B$7 -> 84.924475
A45: =$B$4+0.01 -> 0.12630103 | B45: =(($B$12/(1+$A45)^1)+($C$12/(1+$A45)^2)+($D$12/(1+$A45)^3)+(($D$12*(1+B$40))/($A45-B$40))/(1+$A45)^3-$B$6)/$B$7 -> 60.595781 | C45: =(($B$12/(1+$A45)^1)+($C$12/(1+$A45)^2)+($D$12/(1+$A45)^3)+(($D$12*(1+C$40))/($A45-C$40))/(1+$A45)^3-$B$6)/$B$7 -> 64.258769 | D45: =(($B$12/(1+$A45)^1)+($C$12/(1+$A45)^2)+($D$12/(1+$A45)^3)+(($D$12*(1+D$40))/($A45-D$40))/(1+$A45)^3-$B$6)/$B$7 -> 68.3462 | E45: =(($B$12/(1+$A45)^1)+($C$12/(1+$A45)^2)+($D$12/(1+$A45)^3)+(($D$12*(1+E$40))/($A45-E$40))/(1+$A45)^3-$B$6)/$B$7 -> 72.936384 | F45: =(($B$12/(1+$A45)^1)+($C$12/(1+$A45)^2)+($D$12/(1+$A45)^3)+(($D$12*(1+F$40))/($A45-F$40))/(1+$A45)^3-$B$6)/$B$7 -> 78.128156
A47: Highlighted cell = base-case WACC and terminal growth assumptions.

Sheet Dashboard
A1: APEX INDUSTRIAL TECHNOLOGIES — ANALYST DASHBOARD
A3: Key KPIs
A5: FY2026 Revenue | B5: ='Income Statement'!G4 -> 780
A6: FY2026 EBITDA | B6: ='Income Statement'!G8 -> 150
A7: FY2026 Net Profit | B7: ='Income Statement'!G14 -> 85
A8: FY2026 EBITDA Margin | B8: ='Income Statement'!G16 -> 0.19230769
A9: FY2026 Net Margin | B9: ='Income Statement'!G18 -> 0.10897436
A10: FY2026 Debt / Equity | B10: =Ratios!G10 -> 0.61370717
A11: FY2026 CCC (days) | B11: ='Working Capital'!G7 -> 84.579813
A12: DCF Equity Value | B12: =DCF!B20 -> 797.86122
A14: DCF Value / Share — Base (₹) | B14: =DCF!B21 -> 79.786122
A15: DCF Value / Share — Bear / Bull (₹) | B15: ="₹"&TEXT('Scenario Analysis'!G42,"0.0")&" / ₹"&TEXT('Scenario Analysis'!G44,"0.0") -> ₹65.3 / ₹95.4
A16: Illustrative Rating | B16: ='Executive Summary'!B36 -> HOLD
A17: FY2029E Revenue — Base (₹ cr) | B17: =Forecast!J4 -> 1010.0376
A18: FY2029E EBITDA Margin — Base | B18: =Forecast!J9/Forecast!J4 -> 0.209
B100: 2021 | C100: 2022 | D100: 2023 | E100: 2024 | F100: 2025 | G100: 2026
